<?xml version="1.0"?>
<sdf version='1.7'>
  <model name='ares8_rover'>
    <link name='base_footprint'>
      <inertial>
        <pose>0.007379 -0.000939 0.410545 0 -0 0</pose>
        <mass>10.02</mass>
        <inertia>
          <ixx>0.290769</ixx>
          <ixy>-0.000191861</ixy>
          <ixz>-0.00610475</ixz>
          <iyy>0.415321</iyy>
          <iyz>5.18721e-06</iyz>
          <izz>0.666882</izz>
        </inertia>
      </inertial>
      <collision name='base_footprint_fixed_joint_lump__base_link_collision'>
        <pose>0 0 0.01 0 -0 0</pose>
        <geometry>
          <mesh>
            <scale>0.001 0.001 0.001</scale>
            <uri>/home/karisora/nav_ws/install/nav_rover_control/share/nav_rover_control/meshes/base_link.stl</uri>
          </mesh>
        </geometry>
        <surface>
          <contact>
            <ode/>
          </contact>
          <friction>
            <ode>
              <mu>0.2</mu>
              <mu2>0.2</mu2>
            </ode>
          </friction>
        </surface>
      </collision>
      <visual name='base_footprint_fixed_joint_lump__base_link_visual'>
        <pose>0 0 0.01 0 -0 0</pose>
        <geometry>
          <mesh>
            <scale>0.001 0.001 0.001</scale>
            <uri>/home/karisora/nav_ws/install/nav_rover_control/share/nav_rover_control/meshes/base_link.stl</uri>
          </mesh>
        </geometry>
        <material>
          <script>
            <name>${body_color}</name>
            <uri>file://media/materials/scripts/gazebo.material</uri>
          </script>
        </material>
      </visual>
      <self_collide>1</self_collide>
      <gravity>1</gravity>
      <self_collide>1</self_collide>
      <gravity>1</gravity>
    </link>
    <joint name='lb_str' type='revolute'>
      <pose relative_to='base_footprint'>-0.290355 0.406338 0.421206 0 -0 0</pose>
      <parent>base_footprint</parent>
      <child>steering_link_lb_1</child>
      <axis>
        <xyz>0 0 1</xyz>
        <limit>
          <lower>-1e+16</lower>
          <upper>1e+16</upper>
        </limit>
        <dynamics>
          <spring_reference>0</spring_reference>
          <spring_stiffness>0</spring_stiffness>
        </dynamics>
      </axis>
    </joint>
    <link name='steering_link_lb_1'>
      <pose relative_to='lb_str'>0 0 0 0 -0 0</pose>
      <inertial>
        <pose>7.6e-05 -0.085306 -0.195245 0 -0 0</pose>
        <mass>5.25333</mass>
        <inertia>
          <ixx>0.04929</ixx>
          <ixy>-5e-06</ixy>
          <ixz>-2.8e-05</ixz>
          <iyy>0.038552</iyy>
          <iyz>-0.009932</iyz>
          <izz>0.014173</izz>
        </inertia>
      </inertial>
      <collision name='steering_link_lb_1_collision'>
        <pose>0.290355 -0.406338 -0.411206 0 -0 0</pose>
        <geometry>
          <mesh>
            <scale>0.001 0.001 0.001</scale>
            <uri>/home/karisora/nav_ws/install/nav_rover_control/share/nav_rover_control/meshes/steering_link_lb_1.stl</uri>
          </mesh>
        </geometry>
        <surface>
          <contact>
            <ode/>
          </contact>
          <friction>
            <ode>
              <mu>0.2</mu>
              <mu2>0.2</mu2>
            </ode>
          </friction>
        </surface>
      </collision>
      <visual name='steering_link_lb_1_visual'>
        <pose>0.290355 -0.406338 -0.411206 0 -0 0</pose>
        <geometry>
          <mesh>
            <scale>0.001 0.001 0.001</scale>
            <uri>/home/karisora/nav_ws/install/nav_rover_control/share/nav_rover_control/meshes/steering_link_lb_1.stl</uri>
          </mesh>
        </geometry>
        <material>
          <script>
            <name>${body_color}</name>
            <uri>file://media/materials/scripts/gazebo.material</uri>
          </script>
        </material>
      </visual>
      <self_collide>1</self_collide>
    </link>
    <joint name='lb_tire' type='revolute'>
      <pose relative_to='steering_link_lb_1'>0 -0.017725 -0.2539 0 -0 0</pose>
      <parent>steering_link_lb_1</parent>
      <child>tire_LB_link_1</child>
      <axis>
        <xyz>0 1 0</xyz>
        <limit>
          <lower>-1e+16</lower>
          <upper>1e+16</upper>
        </limit>
        <dynamics>
          <spring_reference>0</spring_reference>
          <spring_stiffness>0</spring_stiffness>
        </dynamics>
      </axis>
    </joint>
    <link name='tire_LB_link_1'>
      <pose relative_to='lb_tire'>0 0 0 0 -0 0</pose>
      <inertial>
        <pose>0.000707 0.020605 -0.000409 0 -0 0</pose>
        <mass>3.0128</mass>
        <inertia>
          <ixx>0.02254</ixx>
          <ixy>4.4e-05</ixy>
          <ixz>0</ixz>
          <iyy>0.039295</iyy>
          <iyz>-2.55e-05</iyz>
          <izz>0.02254</izz>
        </inertia>
      </inertial>
      <collision name='tire_LB_link_1_collision'>
        <pose>0.290355 -0.388613 -0.157306 0 -0 0</pose>
        <geometry>
          <mesh>
            <scale>0.001 0.001 0.001</scale>
            <uri>/home/karisora/nav_ws/install/nav_rover_control/share/nav_rover_control/meshes/tire_LB_link_1.stl</uri>
          </mesh>
        </geometry>
        <surface>
          <contact>
            <ode/>
          </contact>
          <friction>
            <ode>
              <mu>0.8</mu>
              <mu2>0.8</mu2>
            </ode>
          </friction>
        </surface>
      </collision>
      <visual name='tire_LB_link_1_visual'>
        <pose>0.290355 -0.388613 -0.157306 0 -0 0</pose>
        <geometry>
          <mesh>
            <scale>0.001 0.001 0.001</scale>
            <uri>/home/karisora/nav_ws/install/nav_rover_control/share/nav_rover_control/meshes/tire_LB_link_1.stl</uri>
          </mesh>
        </geometry>
        <material>
          <script>
            <name>${body_color}</name>
            <uri>file://media/materials/scripts/gazebo.material</uri>
          </script>
        </material>
      </visual>
      <self_collide>1</self_collide>
    </link>
    <joint name='lf_str' type='revolute'>
      <pose relative_to='base_footprint'>0.419863 0.406338 0.421206 0 -0 0</pose>
      <parent>base_footprint</parent>
      <child>steering_link_lf_1</child>
      <axis>
        <xyz>0 0 -1</xyz>
        <limit>
          <lower>-1e+16</lower>
          <upper>1e+16</upper>
        </limit>
        <dynamics>
          <spring_reference>0</spring_reference>
          <spring_stiffness>0</spring_stiffness>
        </dynamics>
      </axis>
    </joint>
    <link name='steering_link_lf_1'>
      <pose relative_to='lf_str'>0 0 0 0 -0 0</pose>
      <inertial>
        <pose>7.5e-05 -0.085306 -0.195245 0 -0 0</pose>
        <mass>5.25333</mass>
        <inertia>
          <ixx>0.04929</ixx>
          <ixy>-5e-06</ixy>
          <ixz>-2.8e-05</ixz>
          <iyy>0.038552</iyy>
          <iyz>-0.009932</iyz>
          <izz>0.014173</izz>
        </inertia>
      </inertial>
      <collision name='steering_link_lf_1_collision'>
        <pose>-0.419863 -0.406338 -0.411206 0 -0 0</pose>
        <geometry>
          <mesh>
            <scale>0.001 0.001 0.001</scale>
            <uri>/home/karisora/nav_ws/install/nav_rover_control/share/nav_rover_control/meshes/steering_link_lf_1.stl</uri>
          </mesh>
        </geometry>
        <surface>
          <contact>
            <ode/>
          </contact>
          <friction>
            <ode>
              <mu>0.2</mu>
              <mu2>0.2</mu2>
            </ode>
          </friction>
        </surface>
      </collision>
      <visual name='steering_link_lf_1_visual'>
        <pose>-0.419863 -0.406338 -0.411206 0 -0 0</pose>
        <geometry>
          <mesh>
            <scale>0.001 0.001 0.001</scale>
            <uri>/home/karisora/nav_ws/install/nav_rover_control/share/nav_rover_control/meshes/steering_link_lf_1.stl</uri>
          </mesh>
        </geometry>
        <material>
          <script>
            <name>${body_color}</name>
            <uri>file://media/materials/scripts/gazebo.material</uri>
          </script>
        </material>
      </visual>
      <self_collide>1</self_collide>
    </link>
    <joint name='lf_tire' type='revolute'>
      <pose relative_to='steering_link_lf_1'>0 -0.017725 -0.2539 0 -0 0</pose>
      <parent>steering_link_lf_1</parent>
      <child>tire_LF_link_1</child>
      <axis>
        <xyz>0 1 0</xyz>
        <limit>
          <lower>-1e+16</lower>
          <upper>1e+16</upper>
        </limit>
        <dynamics>
          <spring_reference>0</spring_reference>
          <spring_stiffness>0</spring_stiffness>
        </dynamics>
      </axis>
    </joint>
    <link name='tire_LF_link_1'>
      <pose relative_to='lf_tire'>0 0 0 0 -0 0</pose>
      <inertial>
        <pose>0.000707 0.020605 -0.000409 0 -0 0</pose>
        <mass>3.0128</mass>
        <inertia>
          <ixx>0.02254</ixx>
          <ixy>4.4e-05</ixy>
          <ixz>0</ixz>
          <iyy>0.039295</iyy>
          <iyz>-2.55e-05</iyz>
          <izz>0.02254</izz>
        </inertia>
      </inertial>
      <collision name='tire_LF_link_1_collision'>
        <pose>-0.419863 -0.388613 -0.157306 0 -0 0</pose>
        <geometry>
          <mesh>
            <scale>0.001 0.001 0.001</scale>
            <uri>/home/karisora/nav_ws/install/nav_rover_control/share/nav_rover_control/meshes/tire_LF_link_1.stl</uri>
          </mesh>
        </geometry>
        <surface>
          <contact>
            <ode/>
          </contact>
          <friction>
            <ode>
              <mu>0.8</mu>
              <mu2>0.8</mu2>
            </ode>
          </friction>
        </surface>
      </collision>
      <visual name='tire_LF_link_1_visual'>
        <pose>-0.419863 -0.388613 -0.157306 0 -0 0</pose>
        <geometry>
          <mesh>
            <scale>0.001 0.001 0.001</scale>
            <uri>/home/karisora/nav_ws/install/nav_rover_control/share/nav_rover_control/meshes/tire_LF_link_1.stl</uri>
          </mesh>
        </geometry>
        <material>
          <script>
            <name>${body_color}</name>
            <uri>file://media/materials/scripts/gazebo.material</uri>
          </script>
        </material>
      </visual>
      <self_collide>1</self_collide>
    </link>
    <joint name='rb_str' type='revolute'>
      <pose relative_to='base_footprint'>-0.291489 -0.40822 0.421206 0 -0 0</pose>
      <parent>base_footprint</parent>
      <child>steering_link_rb_1</child>
      <axis>
        <xyz>0 0 -1</xyz>
        <limit>
          <lower>-1e+16</lower>
          <upper>1e+16</upper>
        </limit>
        <dynamics>
          <spring_reference>0</spring_reference>
          <spring_stiffness>0</spring_stiffness>
        </dynamics>
      </axis>
    </joint>
    <link name='steering_link_rb_1'>
      <pose relative_to='rb_str'>0 0 0 0 -0 0</pose>
      <inertial>
        <pose>-7.5e-05 0.085306 -0.195245 0 -0 0</pose>
        <mass>5.25333</mass>
        <inertia>
          <ixx>0.04929</ixx>
          <ixy>-5e-06</ixy>
          <ixz>-2.8e-05</ixz>
          <iyy>0.038552</iyy>
          <iyz>-0.009932</iyz>
          <izz>0.014173</izz>
        </inertia>
      </inertial>
      <collision name='steering_link_rb_1_collision'>
        <pose>0.291489 0.40822 -0.411206 0 -0 0</pose>
        <geometry>
          <mesh>
            <scale>0.001 0.001 0.001</scale>
            <uri>/home/karisora/nav_ws/install/nav_rover_control/share/nav_rover_control/meshes/steering_link_rb_1.stl</uri>
          </mesh>
        </geometry>
        <surface>
          <contact>
            <ode/>
          </contact>
          <friction>
            <ode>
              <mu>0.2</mu>
              <mu2>0.2</mu2>
            </ode>
          </friction>
        </surface>
      </collision>
      <visual name='steering_link_rb_1_visual'>
        <pose>0.291489 0.40822 -0.411206 0 -0 0</pose>
        <geometry>
          <mesh>
            <scale>0.001 0.001 0.001</scale>
            <uri>/home/karisora/nav_ws/install/nav_rover_control/share/nav_rover_control/meshes/steering_link_rb_1.stl</uri>
          </mesh>
        </geometry>
        <material>
          <script>
            <name>${body_color}</name>
            <uri>file://media/materials/scripts/gazebo.material</uri>
          </script>
        </material>
      </visual>
      <self_collide>1</self_collide>
    </link>
    <joint name='rb_tire' type='revolute'>
      <pose relative_to='steering_link_rb_1'>0 0.017725 -0.2539 0 -0 0</pose>
      <parent>steering_link_rb_1</parent>
      <child>tire_RB_link_1</child>
      <axis>
        <xyz>0 -1 0</xyz>
        <limit>
          <lower>-1e+16</lower>
          <upper>1e+16</upper>
        </limit>
        <dynamics>
          <spring_reference>0</spring_reference>
          <spring_stiffness>0</spring_stiffness>
        </dynamics>
      </axis>
    </joint>
    <link name='tire_RB_link_1'>
      <pose relative_to='rb_tire'>0 0 0 0 -0 0</pose>
      <inertial>
        <pose>0.000708 -0.020604 -0.000409 0 -0 0</pose>
        <mass>3.0128</mass>
        <inertia>
          <ixx>0.02254</ixx>
          <ixy>4.4e-05</ixy>
          <ixz>0</ixz>
          <iyy>0.039295</iyy>
          <iyz>-2.55e-05</iyz>
          <izz>0.02254</izz>
        </inertia>
      </inertial>
      <collision name='tire_RB_link_1_collision'>
        <pose>0.291489 0.390495 -0.157306 0 -0 0</pose>
        <geometry>
          <mesh>
            <scale>0.001 0.001 0.001</scale>
            <uri>/home/karisora/nav_ws/install/nav_rover_control/share/nav_rover_control/meshes/tire_RB_link_1.stl</uri>
          </mesh>
        </geometry>
        <surface>
          <contact>
            <ode/>
          </contact>
          <friction>
            <ode>
              <mu>0.8</mu>
              <mu2>0.8</mu2>
            </ode>
          </friction>
        </surface>
      </collision>
      <visual name='tire_RB_link_1_visual'>
        <pose>0.291489 0.390495 -0.157306 0 -0 0</pose>
        <geometry>
          <mesh>
            <scale>0.001 0.001 0.001</scale>
            <uri>/home/karisora/nav_ws/install/nav_rover_control/share/nav_rover_control/meshes/tire_RB_link_1.stl</uri>
          </mesh>
        </geometry>
        <material>
          <script>
            <name>${body_color}</name>
            <uri>file://media/materials/scripts/gazebo.material</uri>
          </script>
        </material>
      </visual>
      <self_collide>1</self_collide>
    </link>
    <joint name='rf_str' type='revolute'>
      <pose relative_to='base_footprint'>0.418728 -0.40822 0.421206 0 -0 0</pose>
      <parent>base_footprint</parent>
      <child>steering_link_rf_1</child>
      <axis>
        <xyz>0 0 1</xyz>
        <limit>
          <lower>-1e+16</lower>
          <upper>1e+16</upper>
        </limit>
        <dynamics>
          <spring_reference>0</spring_reference>
          <spring_stiffness>0</spring_stiffness>
        </dynamics>
      </axis>
    </joint>
    <link name='steering_link_rf_1'>
      <pose relative_to='rf_str'>0 0 0 0 -0 0</pose>
      <inertial>
        <pose>-7.5e-05 0.085306 -0.195245 0 -0 0</pose>
        <mass>5.25333</mass>
        <inertia>
          <ixx>0.04929</ixx>
          <ixy>-5e-06</ixy>
          <ixz>-2.8e-05</ixz>
          <iyy>0.038552</iyy>
          <iyz>-0.009932</iyz>
          <izz>0.014173</izz>
        </inertia>
      </inertial>
      <collision name='steering_link_rf_1_collision'>
        <pose>-0.418728 0.40822 -0.411206 0 -0 0</pose>
        <geometry>
          <mesh>
            <scale>0.001 0.001 0.001</scale>
            <uri>/home/karisora/nav_ws/install/nav_rover_control/share/nav_rover_control/meshes/steering_link_rf_1.stl</uri>
          </mesh>
        </geometry>
        <surface>
          <contact>
            <ode/>
          </contact>
          <friction>
            <ode>
              <mu>0.2</mu>
              <mu2>0.2</mu2>
            </ode>
          </friction>
        </surface>
      </collision>
      <visual name='steering_link_rf_1_visual'>
        <pose>-0.418728 0.40822 -0.411206 0 -0 0</pose>
        <geometry>
          <mesh>
            <scale>0.001 0.001 0.001</scale>
            <uri>/home/karisora/nav_ws/install/nav_rover_control/share/nav_rover_control/meshes/steering_link_rf_1.stl</uri>
          </mesh>
        </geometry>
        <material>
          <script>
            <name>${body_color}</name>
            <uri>file://media/materials/scripts/gazebo.material</uri>
          </script>
        </material>
      </visual>
      <self_collide>1</self_collide>
    </link>
    <joint name='rf_tire' type='revolute'>
      <pose relative_to='steering_link_rf_1'>0 0.017725 -0.2539 0 -0 0</pose>
      <parent>steering_link_rf_1</parent>
      <child>tire_RF_link_1</child>
      <axis>
        <xyz>0 -1 0</xyz>
        <limit>
          <lower>-1e+16</lower>
          <upper>1e+16</upper>
        </limit>
        <dynamics>
          <spring_reference>0</spring_reference>
          <spring_stiffness>0</spring_stiffness>
        </dynamics>
      </axis>
    </joint>
    <link name='tire_RF_link_1'>
      <pose relative_to='rf_tire'>0 0 0 0 -0 0</pose>
      <inertial>
        <pose>-0.000707 -0.020604 0.000409 0 -0 0</pose>
        <mass>3.0128</mass>
        <inertia>
          <ixx>0.02254</ixx>
          <ixy>4.4e-05</ixy>
          <ixz>0</ixz>
          <iyy>0.039295</iyy>
          <iyz>-2.55e-05</iyz>
          <izz>0.02254</izz>
        </inertia>
      </inertial>
      <collision name='tire_RF_link_1_collision'>
        <pose>-0.418728 0.390495 -0.157306 0 -0 0</pose>
        <geometry>
          <mesh>
            <scale>0.001 0.001 0.001</scale>
            <uri>/home/karisora/nav_ws/install/nav_rover_control/share/nav_rover_control/meshes/tire_RF_link_1.stl</uri>
          </mesh>
        </geometry>
        <surface>
          <contact>
            <ode/>
          </contact>
          <friction>
            <ode>
              <mu>0.8</mu>
              <mu2>0.8</mu2>
            </ode>
          </friction>
        </surface>
      </collision>
      <visual name='tire_RF_link_1_visual'>
        <pose>-0.418728 0.390495 -0.157306 0 -0 0</pose>
        <geometry>
          <mesh>
            <scale>0.001 0.001 0.001</scale>
            <uri>/home/karisora/nav_ws/install/nav_rover_control/share/nav_rover_control/meshes/tire_RF_link_1.stl</uri>
          </mesh>
        </geometry>
        <material>
          <script>
            <name>${body_color}</name>
            <uri>file://media/materials/scripts/gazebo.material</uri>
          </script>
        </material>
      </visual>
      <self_collide>1</self_collide>
    </link>
    <plugin name='control' filename='libgazebo_ros_control.so'/>
    <plugin name='imu_plugin' filename='libgazebo_ros_imu_sensor.so'>
      <ros>
        <namespace>/</namespace>
      </ros>
      <always_on>1</always_on>
      <update_rate>50.0</update_rate>
      <topic>imu/data</topic>
      <frame_name>imu_link</frame_name>
    </plugin>
    <plugin name='gps_plugin' filename='libgazebo_ros_gps.so'>
      <ros>
        <namespace>/</namespace>
      </ros>
      <update_rate>5.0</update_rate>
      <frame_name>gps_link</frame_name>
      <topic_name>gps/fix</topic_name>
    </plugin>
          <plugin name="turtlebot3_diff_drive" filename="libgazebo_ros_diff_drive.so">

        <ros>
          <!-- <namespace>/tb3</namespace> -->
          <!--since gazebo_plugins publish tf topic in global namespace /tf only and it
            cannot be remapped like (namespace/tf) through launch arguments -->
          <remapping>/tf:=tf</remapping>
        </ros>

        <update_rate>30</update_rate>

        <!-- wheels -->
        <left_joint>lf_tire</left_joint>
        <right_joint>rf_tire</right_joint>

        <!-- kinematics -->
        <wheel_separation>0.287</wheel_separation>
        <wheel_diameter>0.066</wheel_diameter>

        <!-- limits -->
        <max_wheel_torque>20</max_wheel_torque>
        <max_wheel_acceleration>1.0</max_wheel_acceleration>

        <command_topic>cmd_vel</command_topic>

        <!-- output -->
        <!-- The odom -> base link transform is published by the ekf in robot localization -->
        <publish_odom>true</publish_odom>
        <publish_odom_tf>false</publish_odom_tf>
        <publish_wheel_tf>false</publish_wheel_tf>

        <odometry_topic>odom</odometry_topic>
        <odometry_frame>odom</odometry_frame>
        <robot_base_frame>base_footprint</robot_base_frame>

      </plugin>
    <static>0</static>
    <plugin name='four_ws_robot_joint_state' filename='libgazebo_ros_joint_state_publisher.so'>
      <ros>
        <remapping>~/out:=joint_states</remapping>
      </ros>
      <update_rate>30</update_rate>
      <joint_name>lf_tire</joint_name>
      <joint_name>rf_tire</joint_name>
      <joint_name>lb_tire</joint_name>
      <joint_name>rb_tire</joint_name>
      <joint_name>lf_str</joint_name>
      <joint_name>rf_str</joint_name>
      <joint_name>lb_str</joint_name>
      <joint_name>rb_str</joint_name>
    </plugin>
  </model>
</sdf>
