<?xml version="1.0" ?>
<robot name="ares8_rover" xmlns:xacro="http://www.ros.org/wiki/xacro" >

	<xacro:property name="body_color" value="Gazebo/Silver" />
	<material name="silver">
  	<color rgba="0.700 0.700 0.700 1.000"/>
	</material>
	<link name="base_footprint"/>

  <joint name="base_joint" type="fixed">
    <parent link="base_footprint"/>
    <child link="base_link" />
    <origin xyz="0 0 0.010" rpy="0 0 0"/>
  </joint>


	<link name="base_link">
  <inertial>
    <origin xyz="0.007393875774457437 -0.0009412649500128051 0.401095816100654" rpy="0 0 0"/>
    <mass value="10.0"/>
    <inertia ixx="0.289233" iyy="0.413784" izz="0.666879" ixy="-0.000192" iyz="0.0" ixz="-0.006064"/>
  </inertial>
  <visual>
    <origin xyz="0 0 0" rpy="0 0 0"/>
    <geometry>
      <mesh filename="file://$(find nav_rover_control)/meshes/base_link.stl" scale="0.001 0.001 0.001"/>
    </geometry>
    <material name="silver"/>
  </visual>
  <collision>
    <origin xyz="0 0 0" rpy="0 0 0"/>
    <geometry>
      <mesh filename="file://$(find nav_rover_control)/meshes/base_link.stl" scale="0.001 0.001 0.001"/>
    </geometry>
  </collision>
</link>

<link name="steering_link_lf_1">
  <inertial>
    <origin xyz="7.495130477469525e-05 -0.08530635234355655 -0.19524524560699147" rpy="0 0 0"/>
    <mass value="5.253331445605197"/>
    <inertia ixx="0.04929" iyy="0.038552" izz="0.014173" ixy="-5e-06" iyz="-0.009932" ixz="-2.8e-05"/>
  </inertial>
  <visual>
    <origin xyz="-0.419863 -0.406338 -0.411206" rpy="0 0 0"/>
    <geometry>
      <mesh filename="file://$(find nav_rover_control)/meshes/steering_link_lf_1.stl" scale="0.001 0.001 0.001"/>
    </geometry>
    <material name="silver"/>
  </visual>
  <collision>
    <origin xyz="-0.419863 -0.406338 -0.411206" rpy="0 0 0"/>
    <geometry>
      <mesh filename="file://$(find nav_rover_control)/meshes/steering_link_lf_1.stl" scale="0.001 0.001 0.001"/>
    </geometry>
  </collision>
	</link>

	<link name="steering_link_lb_1">
		<inertial>
		  <origin xyz="7.587614450105251e-05 -0.08530635234351625 -0.19524524560699574" rpy="0 0 0"/>
    	<mass value="5.253331445605197"/>
    	<inertia ixx="0.04929" iyy="0.038552" izz="0.014173" ixy="-5e-06" iyz="-0.009932" ixz="-2.8e-05"/>
		</inertial>
		<visual>
		  <origin xyz="0.290355 -0.406338 -0.411206" rpy="0 0 0"/>
		  <geometry>
		    <mesh filename="file://$(find nav_rover_control)/meshes/steering_link_lb_1.stl" scale="0.001 0.001 0.001"/>
		  </geometry>
		  <material name="silver"/>
		</visual>
		<collision>
		  <origin xyz="0.290355 -0.406338 -0.411206" rpy="0 0 0"/>
		  <geometry>
		    <mesh filename="file://$(find nav_rover_control)/meshes/steering_link_lb_1.stl" scale="0.001 0.001 0.001"/>
		  </geometry>
		</collision>
	</link>

	<link name="steering_link_rb_1">
		<inertial>
		  <origin xyz="-7.505592811557493e-05 0.08530582244346485 -0.19524524560691126" rpy="0 0 0"/>
    	<mass value="5.253331445605197"/>
    	<inertia ixx="0.04929" iyy="0.038552" izz="0.014173" ixy="-5e-06" iyz="-0.009932" ixz="-2.8e-05"/>
		</inertial>
		<visual>
		  <origin xyz="0.291489 0.40822 -0.411206" rpy="0 0 0"/>
		  <geometry>
		    <mesh filename="file://$(find nav_rover_control)/meshes/steering_link_rb_1.stl" scale="0.001 0.001 0.001"/>
		  </geometry>
		  <material name="silver"/>
		</visual>
		<collision>
		  <origin xyz="0.291489 0.40822 -0.411206" rpy="0 0 0"/>
		  <geometry>
		    <mesh filename="file://$(find nav_rover_control)/meshes/steering_link_rb_1.stl" scale="0.001 0.001 0.001"/>
		  </geometry>
		</collision>
	</link>

	<link name="steering_link_rf_1">
		<inertial>
		  <origin xyz="-7.498076784201446e-05 0.08530582244346474 -0.19524524560690684" rpy="0 0 0"/>
    	<mass value="5.253331445605197"/>
    	<inertia ixx="0.04929" iyy="0.038552" izz="0.014173" ixy="-5e-06" iyz="-0.009932" ixz="-2.8e-05"/>
		</inertial>
		<visual>
		  <origin xyz="-0.418728 0.40822 -0.411206" rpy="0 0 0"/>
		  <geometry>
		    <mesh filename="file://$(find nav_rover_control)/meshes/steering_link_rf_1.stl" scale="0.001 0.001 0.001"/>
		  </geometry>
		  <material name="silver"/>
		</visual>
		<collision>
		  <origin xyz="-0.418728 0.40822 -0.411206" rpy="0 0 0"/>
		  <geometry>
		    <mesh filename="file://$(find nav_rover_control)/meshes/steering_link_rf_1.stl" scale="0.001 0.001 0.001"/>
		  </geometry>
		</collision>
	</link>

	<link name="tire_LB_link_1">
		<inertial>
		  <origin xyz="0.0007074324264990661 0.020604746349113967 -0.0004088190133060554" rpy="0 0 0"/>
		  <mass value="3.0128049440849543"/>
		  <inertia ixx="0.02254" iyy="0.039295" izz="0.02254" ixy="4.4e-05" iyz="-2.55e-05" ixz="-0.0"/>
		</inertial>
		<visual>
		  <origin xyz="0.290355 -0.388613 -0.157306" rpy="0 0 0"/>
		  <geometry>
		    <mesh filename="file://$(find nav_rover_control)/meshes/tire_LB_link_1.stl" scale="0.001 0.001 0.001"/>
		  </geometry>
		  <material name="silver"/>
		</visual>
		<collision>
		  <origin xyz="0.290355 -0.388613 -0.157306" rpy="0 0 0"/>
		  <geometry>
		    <mesh filename="file://$(find nav_rover_control)/meshes/tire_LB_link_1.stl" scale="0.001 0.001 0.001"/>
		  </geometry>
		</collision>
	</link>

	<link name="tire_LF_link_1">
		<inertial>
		  <origin xyz="0.0007065075867560555 0.02060474634907411 -0.0004088190133018088" rpy="0 0 0"/>
		  <mass value="3.0128049440849543"/>
		  <inertia ixx="0.02254" iyy="0.039295" izz="0.02254" ixy="4.4e-05" iyz="-2.55e-05" ixz="-0.0"/>
		</inertial>
		<visual>
		  <origin xyz="-0.419863 -0.388613 -0.157306" rpy="0 0 0"/>
		  <geometry>
		    <mesh filename="file://$(find nav_rover_control)/meshes/tire_LF_link_1.stl" scale="0.001 0.001 0.001"/>
		  </geometry>
		  <material name="silver"/>
		</visual>
		<collision>
		  <origin xyz="-0.419863 -0.388613 -0.157306" rpy="0 0 0"/>
		  <geometry>
		    <mesh filename="file://$(find nav_rover_control)/meshes/tire_LF_link_1.stl" scale="0.001 0.001 0.001"/>
		  </geometry>
		</collision>
	</link>

	<link name="tire_RB_link_1">
		<inertial>
		  <origin xyz="0.0007077255242637914 -0.020603557729272193 -0.00040885359117279196" rpy="0 0 0"/>
		  <mass value="3.0128049440849543"/>
		  <inertia ixx="0.02254" iyy="0.039295" izz="0.02254" ixy="4.4e-05" iyz="-2.55e-05" ixz="-0.0"/>
		</inertial>
		<visual>
		  <origin xyz="0.291489 0.390495 -0.157306" rpy="0 0 0"/>
		  <geometry>
		    <mesh filename="file://$(find nav_rover_control)/meshes/tire_RB_link_1.stl" scale="0.001 0.001 0.001"/>
		  </geometry>
		  <material name="silver"/>
		</visual>
		<collision>
		  <origin xyz="0.291489 0.390495 -0.157306" rpy="0 0 0"/>
		  <geometry>
		    <mesh filename="file://$(find nav_rover_control)/meshes/tire_RB_link_1.stl" scale="0.001 0.001 0.001"/>
		  </geometry>
		</collision>
	</link>

	<link name="tire_RF_link_1">
		<inertial>
		  <origin xyz="-0.0007069269049217453 -0.020603557729271915 0.00040895944702001863" rpy="0 0 0"/>
		  <mass value="3.0128049440849543"/>
		  <inertia ixx="0.02254" iyy="0.039295" izz="0.02254" ixy="4.4e-05" iyz="-2.55e-05" ixz="-0.0"/>
		</inertial>
		<visual>
		  <origin xyz="-0.418728 0.390495 -0.157306" rpy="0 0 0"/>
		  <geometry>
		    <mesh filename="file://$(find nav_rover_control)/meshes/tire_RF_link_1.stl" scale="0.001 0.001 0.001"/>
		  </geometry>
		  <material name="silver"/>
		</visual>
		<collision>
		  <origin xyz="-0.418728 0.390495 -0.157306" rpy="0 0 0"/>
		  <geometry>
		    <mesh filename="file://$(find nav_rover_control)/meshes/tire_RF_link_1.stl" scale="0.001 0.001 0.001"/>
		  </geometry>
		</collision>
	</link>

	<joint name="lf_str" type="continuous">
		<origin xyz="0.419863 0.406338 0.411206" rpy="0 0 0"/>
		<parent link="base_link"/>
		<child link="steering_link_lf_1"/>
		<axis xyz="0.0 -0.0 -1.0"/>
	</joint>

	<joint name="lb_str" type="continuous">
		<origin xyz="-0.290355 0.406338 0.411206" rpy="0 0 0"/>
		<parent link="base_link"/>
		<child link="steering_link_lb_1"/>
		<axis xyz="-0.0 0.0 1.0"/>
	</joint>

	<joint name="rb_str" type="continuous">
		<origin xyz="-0.291489 -0.40822 0.411206" rpy="0 0 0"/>
		<parent link="base_link"/>
		<child link="steering_link_rb_1"/>
		<axis xyz="0.0 -0.0 -1.0"/>
	</joint>

	<joint name="rf_str" type="continuous">
		<origin xyz="0.418728 -0.40822 0.411206" rpy="0 0 0"/>
		<parent link="base_link"/>
		<child link="steering_link_rf_1"/>
		<axis xyz="-0.0 0.0 1.0"/>
	</joint>

	<joint name="lb_tire" type="continuous">
		<origin xyz="0.0 -0.017725 -0.2539" rpy="0 0 0"/>
		<parent link="steering_link_lb_1"/>
		<child link="tire_LB_link_1"/>
		<axis xyz="0.0 1.0 -0.0"/>
	</joint>

	<joint name="lf_tire" type="continuous">
		<origin xyz="0.0 -0.017725 -0.2539" rpy="0 0 0"/>
		<parent link="steering_link_lf_1"/>
		<child link="tire_LF_link_1"/>
		<axis xyz="-0.0 1.0 -0.0"/>
	</joint>

	<joint name="rb_tire" type="continuous">
		<origin xyz="0.0 0.017725 -0.2539" rpy="0 0 0"/>
		<parent link="steering_link_rb_1"/>
		<child link="tire_RB_link_1"/>
		<axis xyz="0.0 -1.0 0.0"/>
	</joint>

	<joint name="rf_tire" type="continuous">
		<origin xyz="0.0 0.017725 -0.2539" rpy="0 0 0"/>
		<parent link="steering_link_rf_1"/>
		<child link="tire_RF_link_1"/>
		<axis xyz="0.0 -1.0 0.0"/>
	</joint>
</robot>
